<?xml version="1.0" encoding="utf-8"?>
<!-- =================================================================================== -->
<!-- |    This document was autogenerated by xacro from calibration_scene_description.xacro | -->
<!-- |    EDITING THIS FILE BY HAND IS NOT RECOMMENDED                                 | -->
<!-- =================================================================================== -->
<robot name="calibration_scene">
  <!-- environments -->
  <link name="world_base"/>
  <link name="robot_table_link">
    <inertial>
      <origin rpy="0 0 0" xyz="-0.105 -0.05 -0.375"/>
      <mass value="270"/>
      <inertia ixx="20.75625" ixy="9.3207792197652E-16" ixz="-6.95496724866511E-16" iyy="20.75625" iyz="-4.46389240706941E-16" izz="16.2"/>
    </inertial>
    <visual>
      <origin rpy="0 0 0" xyz="0 0 0"/>
      <geometry>
        <mesh filename="package://demo_table_final/meshes/robot_table_link.STL"/>
      </geometry>
      <material name="">
        <color rgba="0.792156862745098 0.819607843137255 0.933333333333333 1"/>
      </material>
    </visual>
    <collision>
      <origin rpy="0 0 0" xyz="0 0 0"/>
      <geometry>
        <mesh filename="package://demo_table_final/meshes/robot_table_link.STL"/>
      </geometry>
    </collision>
  </link>
  <link name="table_link">
    <inertial>
      <origin rpy="0 0 0" xyz="0.00402126708859457 0.035508393002459 -0.124898664646273"/>
      <mass value="168.944"/>
      <inertia ixx="8.44699759847205" ixy="-1.30104260698261E-15" ixz="-2.60208521396521E-15" iyy="71.945357598472" iyz="3.18207682075481E-15" izz="71.4394277333333"/>
    </inertial>
    <visual>
      <origin rpy="0 0 0" xyz="0 0 0"/>
      <geometry>
        <mesh filename="package://demo_table_final/meshes/table_link.STL"/>
      </geometry>
      <material name="">
        <color rgba="0.792156862745098 0.819607843137255 0.933333333333333 1"/>
      </material>
    </visual>
    <collision>
      <origin rpy="0 0 0" xyz="0 0 0"/>
      <geometry>
        <mesh filename="package://demo_table_final/meshes/table_link.STL"/>
      </geometry>
    </collision>
  </link>
  <joint name="tabke_joint" type="fixed">
    <origin rpy="0 0 -1.5707963267949" xyz="0.409491606997541 -0.235978732911405 0.139999999999999"/>
    <parent link="robot_table_link"/>
    <child link="table_link"/>
    <axis xyz="0 0 0"/>
  </joint>
  <link name="cup_table_link">
    <inertial>
      <origin rpy="0 0 0" xyz="-0.00488252735290881 0.0750000000000001 -0.0014947488016297"/>
      <mass value="0.485007210626774"/>
      <inertia ixx="0.0144827661603697" ixy="6.37638257355761E-19" ixz="1.5226158759248E-05" iyy="0.000767879681095258" iyz="2.78003444654154E-20" izz="0.0152414793054048"/>
    </inertial>
    <visual>
      <origin rpy="0 0 0" xyz="0 0 0"/>
      <geometry>
        <mesh filename="package://demo_table_final/meshes/cup_table_link.STL"/>
      </geometry>
      <material name="">
        <color rgba="0.792156862745098 0.819607843137255 0.933333333333333 1"/>
      </material>
    </visual>
    <collision>
      <origin rpy="0 0 0" xyz="0 0 0"/>
      <geometry>
        <mesh filename="package://demo_table_final/meshes/cup_table_link.STL"/>
      </geometry>
    </collision>
  </link>
  <joint name="cup_table_joint" type="fixed">
    <origin rpy="0 0 1.5707963267949" xyz="-0.525978732911406 0.215557219161956 0.005"/>
    <parent link="table_link"/>
    <child link="cup_table_link"/>
    <axis xyz="0 0 0"/>
  </joint>
  <link name="plate_table_link">
    <inertial>
      <origin rpy="0 0 0" xyz="0.0821309141789029 -0.14 -0.0780889544369172"/>
      <mass value="27.7659"/>
      <inertia ixx="0.812008207991436" ixy="-2.15177346128204E-17" ixz="0.000861743605069532" iyy="0.273754933724942" iyz="1.39808683446883E-17" izz="0.967215330733505"/>
    </inertial>
    <visual>
      <origin rpy="0 0 0" xyz="0 0 0"/>
      <geometry>
        <mesh filename="package://demo_table_final/meshes/plate_table_link.STL"/>
      </geometry>
      <material name="">
        <color rgba="0.792156862745098 0.819607843137255 0.933333333333333 1"/>
      </material>
    </visual>
    <collision>
      <origin rpy="0 0 0" xyz="0 0 0"/>
      <geometry>
        <mesh filename="package://demo_table_final/meshes/plate_table_link.STL"/>
      </geometry>
    </collision>
  </link>
  <joint name="plate_table_joint" type="fixed">
    <origin rpy="0 0 1.5707963267949" xyz="-0.140978732911405 0.050508393002459 0.158"/>
    <parent link="table_link"/>
    <child link="plate_table_link"/>
    <axis xyz="0 0 0"/>
  </joint>
  <joint name="world-env_joint" type="fixed">
    <origin rpy="0 0 0" xyz="0 0 0"/>
    <parent link="world_base"/>
    <child link="robot_table_link"/>
  </joint>
  <!-- Conversion were obtained from http://www.e-paint.co.uk/Lab_values.asp
       unless otherwise stated. -->
  <!-- link list -->
  <link name="irb120_base_link">
    <inertial>
      <mass value="6.215"/>
      <origin rpy="0 0 0" xyz="-0.04204 8.01E-05 0.07964"/>
      <inertia ixx="0.0247272" ixy="-8.0784E-05" ixz="0.00130902" iyy="0.0491285" iyz="-8.0419E-06" izz="0.0472376"/>
    </inertial>
    <visual>
      <origin rpy="0 0 0" xyz="0 0 0"/>
      <geometry>
        <mesh filename="package://irb120_description/meshes/visual/base_link.stl"/>
      </geometry>
      <material name="">
        <color rgba="0.9254902 0.9254902 0.9058824 1"/>
      </material>
    </visual>
    <collision>
      <origin rpy="0 0 0" xyz="0 0 0"/>
      <geometry>
        <mesh filename="package://irb120_description/meshes/collision/base_link.stl"/>
      </geometry>
      <material name="">
        <color rgba="1 1 0 1"/>
      </material>
    </collision>
  </link>
  <link name="irb120_link_1">
    <inertial>
      <mass value="3.067"/>
      <origin rpy="0 0 0" xyz="9.77E-05 -0.00012 0.23841"/>
      <inertia ixx="0.0142175" ixy="-1.28579E-05" ixz="-2.31364E-05" iyy="0.0144041" iyz="1.93404E-05" izz="0.0104533"/>
    </inertial>
    <visual>
      <origin rpy="0 0 0" xyz="0 0 0"/>
      <geometry>
        <mesh filename="package://irb120_description/meshes/visual/link_1.stl"/>
      </geometry>
      <material name="">
        <color rgba="0.9254902 0.9254902 0.9058824 1"/>
      </material>
    </visual>
    <collision>
      <origin rpy="0 0 0" xyz="0 0 0"/>
      <geometry>
        <mesh filename="package://irb120_description/meshes/collision/link_1.stl"/>
      </geometry>
      <material name="">
        <color rgba="1 1 0 1"/>
      </material>
    </collision>
  </link>
  <link name="irb120_link_2">
    <inertial>
      <mass value="3.909"/>
      <origin rpy="0 0 0" xyz="0.00078 -0.00212 0.10124"/>
      <inertia ixx="0.0603111" ixy="9.83431E-06" ixz="5.72407E-05" iyy="0.041569" iyz="-0.00050497" izz="0.0259548"/>
    </inertial>
    <visual>
      <origin rpy="0 0 0" xyz="0 0 0"/>
      <geometry>
        <mesh filename="package://irb120_description/meshes/visual/link_2.stl"/>
      </geometry>
      <material name="">
        <color rgba="0.9254902 0.9254902 0.9058824 1"/>
      </material>
    </visual>
    <collision>
      <origin rpy="0 0 0" xyz="0 0 0"/>
      <geometry>
        <mesh filename="package://irb120_description/meshes/collision/link_2.stl"/>
      </geometry>
      <material name="">
        <color rgba="1 1 0 1"/>
      </material>
    </collision>
  </link>
  <link name="irb120_link_3">
    <inertial>
      <mass value="2.944"/>
      <origin rpy="0 0 0" xyz="0.02281 0.00106 0.05791"/>
      <inertia ixx="0.00835606" ixy="-8.01545E-05" ixz="0.00142884" iyy="0.016713" iyz="-0.000182227" izz="0.0126984"/>
    </inertial>
    <visual>
      <origin rpy="0 0 0" xyz="0 0 0"/>
      <geometry>
        <mesh filename="package://irb120_description/meshes/visual/link_3.stl"/>
      </geometry>
      <material name="">
        <color rgba="0.9254902 0.9254902 0.9058824 1"/>
      </material>
    </visual>
    <collision>
      <origin rpy="0 0 0" xyz="0 0 0"/>
      <geometry>
        <mesh filename="package://irb120_description/meshes/collision/link_3.stl"/>
      </geometry>
      <material name="">
        <color rgba="1 1 0 1"/>
      </material>
    </collision>
  </link>
  <link name="irb120_link_4">
    <inertial>
      <mass value="1.328"/>
      <origin rpy="0 0 0" xyz="0.2247 0.00015 0.00041"/>
      <inertia ixx="0.00284661" ixy="-2.12765E-05" ixz="-1.6435E-05" iyy="0.00401346" iyz="1.31336E-05" izz="0.0052535"/>
    </inertial>
    <visual>
      <origin rpy="0 0 0" xyz="0 0 0"/>
      <geometry>
        <mesh filename="package://irb120_description/meshes/visual/link_4.stl"/>
      </geometry>
      <material name="">
        <color rgba="0.9254902 0.9254902 0.9058824 1"/>
      </material>
    </visual>
    <collision>
      <origin rpy="0 0 0" xyz="0 0 0"/>
      <geometry>
        <mesh filename="package://irb120_description/meshes/collision/link_4.stl"/>
      </geometry>
      <material name="">
        <color rgba="1 1 0 1"/>
      </material>
    </collision>
  </link>
  <link name="irb120_link_5">
    <inertial>
      <mass value="0.546"/>
      <origin rpy="0 0 0" xyz="-0.00109 3.68E-05 6.22E-05"/>
      <inertia ixx="0.000404891" ixy="1.61943E-06" ixz="8.46805E-07" iyy="0.000892825" iyz="-1.51792E-08" izz="0.000815468"/>
    </inertial>
    <visual>
      <origin rpy="0 0 0" xyz="0 0 0"/>
      <geometry>
        <mesh filename="package://irb120_description/meshes/visual/link_5.stl"/>
      </geometry>
      <material name="">
        <color rgba="0.9254902 0.9254902 0.9058824 1"/>
      </material>
    </visual>
    <collision>
      <origin rpy="0 0 0" xyz="0 0 0"/>
      <geometry>
        <mesh filename="package://irb120_description/meshes/collision/link_5.stl"/>
      </geometry>
      <material name="">
        <color rgba="1 1 0 1"/>
      </material>
    </collision>
  </link>
  <link name="irb120_link_6">
    <inertial>
      <mass value="0.137"/>
      <origin rpy="0 0 0" xyz="-0.00706 -0.00017 -1.32E-06"/>
      <inertia ixx="0.001" ixy="0" ixz="0" iyy="0.001" iyz="0" izz="0.001"/>
    </inertial>
    <visual>
      <origin rpy="0 0 0" xyz="0 0 0"/>
      <geometry>
        <mesh filename="package://irb120_description/meshes/visual/link_6.stl"/>
      </geometry>
      <material name="">
        <color rgba="0.1882353 0.1960784 0.2039216 1"/>
      </material>
    </visual>
    <collision>
      <origin rpy="0 0 0" xyz="0 0 0"/>
      <geometry>
        <mesh filename="package://irb120_description/meshes/collision/link_6.stl"/>
      </geometry>
      <material name="">
        <color rgba="1 1 0 1"/>
      </material>
    </collision>
  </link>
  <!-- end of link list -->
  <!-- joint list -->
  <joint name="irb120_joint_1" type="revolute">
    <origin rpy="0 0 0" xyz="0 0 0"/>
    <parent link="irb120_base_link"/>
    <child link="irb120_link_1"/>
    <limit effort="30" lower="-2.87979" upper="2.87979" velocity="4.36332"/>
    <axis xyz="0 0 1"/>
    <dynamics damping="0.0" friction="0.0"/>
  </joint>
  <joint name="irb120_joint_2" type="revolute">
    <origin rpy="0 0 0" xyz="0 0 0.29"/>
    <parent link="irb120_link_1"/>
    <child link="irb120_link_2"/>
    <limit effort="30" lower="-1.91986" upper="1.91986" velocity="4.36332"/>
    <axis xyz="0 1 0"/>
    <dynamics damping="0.0" friction="0.0"/>
  </joint>
  <joint name="irb120_joint_3" type="revolute">
    <origin rpy="0 0 0" xyz="0 0 0.27"/>
    <parent link="irb120_link_2"/>
    <child link="irb120_link_3"/>
    <limit effort="30" lower="-1.91986" upper="1.22173" velocity="4.36332"/>
    <axis xyz="0 1 0"/>
    <dynamics damping="0.0" friction="0.0"/>
  </joint>
  <joint name="irb120_joint_4" type="revolute">
    <origin rpy="0 0 0" xyz="0 0 0.07"/>
    <parent link="irb120_link_3"/>
    <child link="irb120_link_4"/>
    <limit effort="30" lower="-2.79253" upper="2.79253" velocity="5.58505"/>
    <axis xyz="1 0 0"/>
    <dynamics damping="0.0" friction="0.0"/>
  </joint>
  <joint name="irb120_joint_5" type="revolute">
    <origin rpy="0 0 0" xyz="0.302 0 0"/>
    <parent link="irb120_link_4"/>
    <child link="irb120_link_5"/>
    <limit effort="30" lower="-2.094395" upper="2.094395" velocity="5.58505"/>
    <axis xyz="0 1 0"/>
    <dynamics damping="0.0" friction="0.0"/>
  </joint>
  <joint name="irb120_joint_6" type="revolute">
    <origin rpy="0 0 0" xyz="0.072 0 0"/>
    <parent link="irb120_link_5"/>
    <child link="irb120_link_6"/>
    <!-- <limit effort="30" lower="-6.98132" upper="6.98132" velocity="7.33038"/> -->
    <limit effort="30" lower="-3.752457892" upper="3.752457892" velocity="7.33038"/>
    <axis xyz="1 0 0"/>
    <dynamics damping="0.0" friction="0.0"/>
  </joint>
  <!-- end of joint list -->
  <!-- ROS-Industrial 'base' frame: base_link to ABB World Coordinates transform -->
  <link name="irb120_base"/>
  <joint name="irb120_base_link-base" type="fixed">
    <origin rpy="0 0 0" xyz="0 0 0"/>
    <axis xyz="0 0 0"/>
    <parent link="irb120_base"/>
    <child link="irb120_base_link"/>
  </joint>
  <!-- ROS-Industrial 'flange' frame: attachment point for EEF models -->
  <link name="irb120_flange"/>
  <joint name="irb120_joint_6-flange" type="fixed">
    <origin rpy="0 0 0" xyz="0 0 0"/>
    <parent link="irb120_link_6"/>
    <child link="irb120_flange"/>
  </joint>
  <!-- ROS-Industrial 'tool0' frame: all-zeros tool frame -->
  <link name="irb120_tool0"/>
  <joint name="irb120_link_6-tool0" type="fixed">
    <origin rpy="0 1.57079632679 0" xyz="0 0 0"/>
    <parent link="irb120_flange"/>
    <child link="irb120_tool0"/>
  </joint>
  <joint name="world-irb120_joint" type="fixed">
    <!-- <origin xyz="0.3625 -0.1125 0" rpy="0 0 ${PI}"/> -->
    <!-- <origin xyz="0.21 0 0" rpy="0 0 0"/> -->
    <origin rpy="0 0 1.5707963267949" xyz="0 0 0"/>
    <parent link="world_base"/>
    <child link="irb120_base"/>
  </joint>
  <link name="irb120_calib_irb120_mount">
    <inertial>
      <origin rpy="0 0 0" xyz="-8.12565780551138E-05 -0.00287805849749058 -3.52248683292909E-19"/>
      <mass value="0.0209349166233355"/>
      <inertia ixx="4.95778958493382E-06" ixy="1.97846625513937E-10" ixz="-4.43831754358549E-23" iyy="9.71241755254459E-06" iyz="-2.75701045324081E-22" izz="5.03139901662538E-06"/>
    </inertial>
    <visual>
      <origin rpy="0 0 0" xyz="0 0 0"/>
      <geometry>
        <mesh filename="package://camera_calibration_tool_irb120/meshes/calib_irb120_mount.STL"/>
      </geometry>
      <material name="">
        <color rgba="0.792156862745098 0.819607843137255 0.933333333333333 1"/>
      </material>
    </visual>
    <collision>
      <origin rpy="0 0 0" xyz="0 0 0"/>
      <geometry>
        <mesh filename="package://camera_calibration_tool_irb120/meshes/calib_irb120_mount.STL"/>
      </geometry>
    </collision>
  </link>
  <link name="irb120_calib_chessboard_mount">
    <inertial>
      <origin rpy="0 0 0" xyz="-3.45867604983378E-17 -0.00894935918184562 0.0168899392357391"/>
      <mass value="0.051158149759327"/>
      <inertia ixx="1.66225607083464E-05" ixy="-3.06301449855151E-22" ixz="8.3201613309091E-22" iyy="1.74442705550819E-05" iyz="3.7130506703622E-06" izz="2.00339404612724E-05"/>
    </inertial>
    <visual>
      <origin rpy="0 0 0" xyz="0 0 0"/>
      <geometry>
        <mesh filename="package://camera_calibration_tool_irb120/meshes/calib_chessboard_mount.STL"/>
      </geometry>
      <material name="">
        <color rgba="0.792156862745098 0.819607843137255 0.933333333333333 1"/>
      </material>
    </visual>
    <collision>
      <origin rpy="0 0 0" xyz="0 0 0"/>
      <geometry>
        <mesh filename="package://camera_calibration_tool_irb120/meshes/calib_chessboard_mount.STL"/>
      </geometry>
    </collision>
  </link>
  <joint name="irb120_calib_mount_joint" type="fixed">
    <origin rpy="1.5708 0 0" xyz="0 -0.006 0"/>
    <parent link="irb120_calib_irb120_mount"/>
    <child link="irb120_calib_chessboard_mount"/>
    <axis xyz="0 0 0"/>
  </joint>
  <link name="irb120_calib_chessboard">
    <inertial>
      <origin rpy="0 0 0" xyz="9.22626218376613E-18 -0.00587706046456411 0.00249956082033895"/>
      <mass value="0.153331049840439"/>
      <inertia ixx="0.000390178689718211" ixy="4.45302065945594E-20" ixz="-1.10250787557035E-21" iyy="0.000391719917576771" iyz="-6.27088743359988E-09" izz="0.00078125964975703"/>
    </inertial>
    <visual>
      <origin rpy="0 0 0" xyz="0 0 0"/>
      <geometry>
        <mesh filename="package://camera_calibration_tool_irb120/meshes/calib_chessboard.STL"/>
      </geometry>
      <material name="">
        <color rgba="0.792156862745098 0.819607843137255 0.933333333333333 1"/>
      </material>
    </visual>
    <collision>
      <origin rpy="0 0 0" xyz="0 0 0"/>
      <geometry>
        <mesh filename="package://camera_calibration_tool_irb120/meshes/calib_chessboard.STL"/>
      </geometry>
    </collision>
  </link>
  <joint name="irb120_calib_chessboard_joint" type="fixed">
    <origin rpy="1.5708 0 0" xyz="0 0 0.124"/>
    <parent link="irb120_calib_chessboard_mount"/>
    <child link="irb120_calib_chessboard"/>
    <axis xyz="0 0 0"/>
  </joint>
  <joint name="irb120-calib_joint" type="fixed">
    <parent link="irb120_tool0"/>
    <child link="irb120_calib_irb120_mount"/>
    <origin rpy="-1.570796327 0 1.570796327" xyz="0 0 0"/>
  </joint>
  <!-- irb120 calibration board center point -->
  <link name="irb120_calib_center_point">
    <visual>
      <origin rpy="0 0 0" xyz="0 0 0"/>
      <geometry>
        <sphere radius="0.005"/>
      </geometry>
      <material name="irb120_calib_center_point">
        <color rgba="1 0 1 0.1"/>
      </material>
    </visual>
  </link>
  <joint name="irb120_calib_center_point_joint" type="fixed">
    <parent link="irb120_calib_irb120_mount"/>
    <child link="irb120_calib_center_point"/>
    <origin rpy="0 0 0" xyz="0 -0.13 0"/>
  </joint>
</robot>

