<?xml version="1.0" encoding="utf-8"?>
<!-- =================================================================================== -->
<!-- |    This document was autogenerated by xacro from full_scene_description.xacro   | -->
<!-- |    EDITING THIS FILE BY HAND IS NOT RECOMMENDED                                 | -->
<!-- =================================================================================== -->
<robot name="full_scene">
  <!-- environments -->
  <link name="world_base"/>
  <link name="robot_table_link">
    <inertial>
      <origin rpy="0 0 0" xyz="-0.105 -0.05 -0.375"/>
      <mass value="270"/>
      <inertia ixx="20.75625" ixy="9.3207792197652E-16" ixz="-6.95496724866511E-16" iyy="20.75625" iyz="-4.46389240706941E-16" izz="16.2"/>
    </inertial>
    <visual>
      <origin rpy="0 0 0" xyz="0 0 0"/>
      <geometry>
        <mesh filename="package://demo_table_final/meshes/robot_table_link.STL"/>
      </geometry>
      <material name="">
        <color rgba="0.792156862745098 0.819607843137255 0.933333333333333 1"/>
      </material>
    </visual>
    <collision>
      <origin rpy="0 0 0" xyz="0 0 0"/>
      <geometry>
        <mesh filename="package://demo_table_final/meshes/robot_table_link.STL"/>
      </geometry>
    </collision>
  </link>
  <link name="table_link">
    <inertial>
      <origin rpy="0 0 0" xyz="0.00402126708859457 0.035508393002459 -0.124898664646273"/>
      <mass value="168.944"/>
      <inertia ixx="8.44699759847205" ixy="-1.30104260698261E-15" ixz="-2.60208521396521E-15" iyy="71.945357598472" iyz="3.18207682075481E-15" izz="71.4394277333333"/>
    </inertial>
    <visual>
      <origin rpy="0 0 0" xyz="0 0 0"/>
      <geometry>
        <mesh filename="package://demo_table_final/meshes/table_link.STL"/>
      </geometry>
      <material name="">
        <color rgba="0.792156862745098 0.819607843137255 0.933333333333333 1"/>
      </material>
    </visual>
    <collision>
      <origin rpy="0 0 0" xyz="0 0 0"/>
      <geometry>
        <mesh filename="package://demo_table_final/meshes/table_link.STL"/>
      </geometry>
    </collision>
  </link>
  <joint name="tabke_joint" type="fixed">
    <origin rpy="0 0 -1.5707963267949" xyz="0.409491606997541 -0.235978732911405 0.139999999999999"/>
    <parent link="robot_table_link"/>
    <child link="table_link"/>
    <axis xyz="0 0 0"/>
  </joint>
  <link name="cup_table_link">
    <inertial>
      <origin rpy="0 0 0" xyz="-0.00488252735290881 0.0750000000000001 -0.0014947488016297"/>
      <mass value="0.485007210626774"/>
      <inertia ixx="0.0144827661603697" ixy="6.37638257355761E-19" ixz="1.5226158759248E-05" iyy="0.000767879681095258" iyz="2.78003444654154E-20" izz="0.0152414793054048"/>
    </inertial>
    <visual>
      <origin rpy="0 0 0" xyz="0 0 0"/>
      <geometry>
        <mesh filename="package://demo_table_final/meshes/cup_table_link.STL"/>
      </geometry>
      <material name="">
        <color rgba="0.792156862745098 0.819607843137255 0.933333333333333 1"/>
      </material>
    </visual>
    <collision>
      <origin rpy="0 0 0" xyz="0 0 0"/>
      <geometry>
        <mesh filename="package://demo_table_final/meshes/cup_table_link.STL"/>
      </geometry>
    </collision>
  </link>
  <joint name="cup_table_joint" type="fixed">
    <origin rpy="0 0 1.5707963267949" xyz="-0.525978732911406 0.215557219161956 0.005"/>
    <parent link="table_link"/>
    <child link="cup_table_link"/>
    <axis xyz="0 0 0"/>
  </joint>
  <link name="plate_table_link">
    <inertial>
      <origin rpy="0 0 0" xyz="0.0821309141789029 -0.14 -0.0780889544369172"/>
      <mass value="27.7659"/>
      <inertia ixx="0.812008207991436" ixy="-2.15177346128204E-17" ixz="0.000861743605069532" iyy="0.273754933724942" iyz="1.39808683446883E-17" izz="0.967215330733505"/>
    </inertial>
    <visual>
      <origin rpy="0 0 0" xyz="0 0 0"/>
      <geometry>
        <mesh filename="package://demo_table_final/meshes/plate_table_link.STL"/>
      </geometry>
      <material name="">
        <color rgba="0.792156862745098 0.819607843137255 0.933333333333333 1"/>
      </material>
    </visual>
    <collision>
      <origin rpy="0 0 0" xyz="0 0 0"/>
      <geometry>
        <mesh filename="package://demo_table_final/meshes/plate_table_link.STL"/>
      </geometry>
    </collision>
  </link>
  <joint name="plate_table_joint" type="fixed">
    <origin rpy="0 0 1.5707963267949" xyz="-0.140978732911405 0.050508393002459 0.158"/>
    <parent link="table_link"/>
    <child link="plate_table_link"/>
    <axis xyz="0 0 0"/>
  </joint>
  <joint name="world-env_joint" type="fixed">
    <origin rpy="0 0 0" xyz="0 0 0"/>
    <parent link="world_base"/>
    <child link="robot_table_link"/>
  </joint>
  <!-- Conversion were obtained from http://www.e-paint.co.uk/Lab_values.asp
       unless otherwise stated. -->
  <!-- link list -->
  <link name="irb120_base_link">
    <inertial>
      <mass value="6.215"/>
      <origin rpy="0 0 0" xyz="-0.04204 8.01E-05 0.07964"/>
      <inertia ixx="0.0247272" ixy="-8.0784E-05" ixz="0.00130902" iyy="0.0491285" iyz="-8.0419E-06" izz="0.0472376"/>
    </inertial>
    <visual>
      <origin rpy="0 0 0" xyz="0 0 0"/>
      <geometry>
        <mesh filename="package://irb120_description/meshes/visual/base_link.stl"/>
      </geometry>
      <material name="">
        <color rgba="0.9254902 0.9254902 0.9058824 1"/>
      </material>
    </visual>
    <collision>
      <origin rpy="0 0 0" xyz="0 0 0"/>
      <geometry>
        <mesh filename="package://irb120_description/meshes/collision/base_link.stl"/>
      </geometry>
      <material name="">
        <color rgba="1 1 0 1"/>
      </material>
    </collision>
  </link>
  <link name="irb120_link_1">
    <inertial>
      <mass value="3.067"/>
      <origin rpy="0 0 0" xyz="9.77E-05 -0.00012 0.23841"/>
      <inertia ixx="0.0142175" ixy="-1.28579E-05" ixz="-2.31364E-05" iyy="0.0144041" iyz="1.93404E-05" izz="0.0104533"/>
    </inertial>
    <visual>
      <origin rpy="0 0 0" xyz="0 0 0"/>
      <geometry>
        <mesh filename="package://irb120_description/meshes/visual/link_1.stl"/>
      </geometry>
      <material name="">
        <color rgba="0.9254902 0.9254902 0.9058824 1"/>
      </material>
    </visual>
    <collision>
      <origin rpy="0 0 0" xyz="0 0 0"/>
      <geometry>
        <mesh filename="package://irb120_description/meshes/collision/link_1.stl"/>
      </geometry>
      <material name="">
        <color rgba="1 1 0 1"/>
      </material>
    </collision>
  </link>
  <link name="irb120_link_2">
    <inertial>
      <mass value="3.909"/>
      <origin rpy="0 0 0" xyz="0.00078 -0.00212 0.10124"/>
      <inertia ixx="0.0603111" ixy="9.83431E-06" ixz="5.72407E-05" iyy="0.041569" iyz="-0.00050497" izz="0.0259548"/>
    </inertial>
    <visual>
      <origin rpy="0 0 0" xyz="0 0 0"/>
      <geometry>
        <mesh filename="package://irb120_description/meshes/visual/link_2.stl"/>
      </geometry>
      <material name="">
        <color rgba="0.9254902 0.9254902 0.9058824 1"/>
      </material>
    </visual>
    <collision>
      <origin rpy="0 0 0" xyz="0 0 0"/>
      <geometry>
        <mesh filename="package://irb120_description/meshes/collision/link_2.stl"/>
      </geometry>
      <material name="">
        <color rgba="1 1 0 1"/>
      </material>
    </collision>
  </link>
  <link name="irb120_link_3">
    <inertial>
      <mass value="2.944"/>
      <origin rpy="0 0 0" xyz="0.02281 0.00106 0.05791"/>
      <inertia ixx="0.00835606" ixy="-8.01545E-05" ixz="0.00142884" iyy="0.016713" iyz="-0.000182227" izz="0.0126984"/>
    </inertial>
    <visual>
      <origin rpy="0 0 0" xyz="0 0 0"/>
      <geometry>
        <mesh filename="package://irb120_description/meshes/visual/link_3.stl"/>
      </geometry>
      <material name="">
        <color rgba="0.9254902 0.9254902 0.9058824 1"/>
      </material>
    </visual>
    <collision>
      <origin rpy="0 0 0" xyz="0 0 0"/>
      <geometry>
        <mesh filename="package://irb120_description/meshes/collision/link_3.stl"/>
      </geometry>
      <material name="">
        <color rgba="1 1 0 1"/>
      </material>
    </collision>
  </link>
  <link name="irb120_link_4">
    <inertial>
      <mass value="1.328"/>
      <origin rpy="0 0 0" xyz="0.2247 0.00015 0.00041"/>
      <inertia ixx="0.00284661" ixy="-2.12765E-05" ixz="-1.6435E-05" iyy="0.00401346" iyz="1.31336E-05" izz="0.0052535"/>
    </inertial>
    <visual>
      <origin rpy="0 0 0" xyz="0 0 0"/>
      <geometry>
        <mesh filename="package://irb120_description/meshes/visual/link_4.stl"/>
      </geometry>
      <material name="">
        <color rgba="0.9254902 0.9254902 0.9058824 1"/>
      </material>
    </visual>
    <collision>
      <origin rpy="0 0 0" xyz="0 0 0"/>
      <geometry>
        <mesh filename="package://irb120_description/meshes/collision/link_4.stl"/>
      </geometry>
      <material name="">
        <color rgba="1 1 0 1"/>
      </material>
    </collision>
  </link>
  <link name="irb120_link_5">
    <inertial>
      <mass value="0.546"/>
      <origin rpy="0 0 0" xyz="-0.00109 3.68E-05 6.22E-05"/>
      <inertia ixx="0.000404891" ixy="1.61943E-06" ixz="8.46805E-07" iyy="0.000892825" iyz="-1.51792E-08" izz="0.000815468"/>
    </inertial>
    <visual>
      <origin rpy="0 0 0" xyz="0 0 0"/>
      <geometry>
        <mesh filename="package://irb120_description/meshes/visual/link_5.stl"/>
      </geometry>
      <material name="">
        <color rgba="0.9254902 0.9254902 0.9058824 1"/>
      </material>
    </visual>
    <collision>
      <origin rpy="0 0 0" xyz="0 0 0"/>
      <geometry>
        <mesh filename="package://irb120_description/meshes/collision/link_5.stl"/>
      </geometry>
      <material name="">
        <color rgba="1 1 0 1"/>
      </material>
    </collision>
  </link>
  <link name="irb120_link_6">
    <inertial>
      <mass value="0.137"/>
      <origin rpy="0 0 0" xyz="-0.00706 -0.00017 -1.32E-06"/>
      <inertia ixx="0.001" ixy="0" ixz="0" iyy="0.001" iyz="0" izz="0.001"/>
    </inertial>
    <visual>
      <origin rpy="0 0 0" xyz="0 0 0"/>
      <geometry>
        <mesh filename="package://irb120_description/meshes/visual/link_6.stl"/>
      </geometry>
      <material name="">
        <color rgba="0.1882353 0.1960784 0.2039216 1"/>
      </material>
    </visual>
    <collision>
      <origin rpy="0 0 0" xyz="0 0 0"/>
      <geometry>
        <mesh filename="package://irb120_description/meshes/collision/link_6.stl"/>
      </geometry>
      <material name="">
        <color rgba="1 1 0 1"/>
      </material>
    </collision>
  </link>
  <!-- end of link list -->
  <!-- joint list -->
  <joint name="irb120_joint_1" type="revolute">
    <origin rpy="0 0 0" xyz="0 0 0"/>
    <parent link="irb120_base_link"/>
    <child link="irb120_link_1"/>
    <limit effort="30" lower="-2.87979" upper="2.87979" velocity="4.36332"/>
    <axis xyz="0 0 1"/>
    <dynamics damping="0.0" friction="0.0"/>
  </joint>
  <joint name="irb120_joint_2" type="revolute">
    <origin rpy="0 0 0" xyz="0 0 0.29"/>
    <parent link="irb120_link_1"/>
    <child link="irb120_link_2"/>
    <limit effort="30" lower="-1.91986" upper="1.91986" velocity="4.36332"/>
    <axis xyz="0 1 0"/>
    <dynamics damping="0.0" friction="0.0"/>
  </joint>
  <joint name="irb120_joint_3" type="revolute">
    <origin rpy="0 0 0" xyz="0 0 0.27"/>
    <parent link="irb120_link_2"/>
    <child link="irb120_link_3"/>
    <limit effort="30" lower="-1.91986" upper="1.22173" velocity="4.36332"/>
    <axis xyz="0 1 0"/>
    <dynamics damping="0.0" friction="0.0"/>
  </joint>
  <joint name="irb120_joint_4" type="revolute">
    <origin rpy="0 0 0" xyz="0 0 0.07"/>
    <parent link="irb120_link_3"/>
    <child link="irb120_link_4"/>
    <limit effort="30" lower="-2.79253" upper="2.79253" velocity="5.58505"/>
    <axis xyz="1 0 0"/>
    <dynamics damping="0.0" friction="0.0"/>
  </joint>
  <joint name="irb120_joint_5" type="revolute">
    <origin rpy="0 0 0" xyz="0.302 0 0"/>
    <parent link="irb120_link_4"/>
    <child link="irb120_link_5"/>
    <limit effort="30" lower="-2.094395" upper="2.094395" velocity="5.58505"/>
    <axis xyz="0 1 0"/>
    <dynamics damping="0.0" friction="0.0"/>
  </joint>
  <joint name="irb120_joint_6" type="revolute">
    <origin rpy="0 0 0" xyz="0.072 0 0"/>
    <parent link="irb120_link_5"/>
    <child link="irb120_link_6"/>
    <!-- <limit effort="30" lower="-6.98132" upper="6.98132" velocity="7.33038"/> -->
    <limit effort="30" lower="-3.752457892" upper="3.752457892" velocity="7.33038"/>
    <axis xyz="1 0 0"/>
    <dynamics damping="0.0" friction="0.0"/>
  </joint>
  <!-- end of joint list -->
  <!-- ROS-Industrial 'base' frame: base_link to ABB World Coordinates transform -->
  <link name="irb120_base"/>
  <joint name="irb120_base_link-base" type="fixed">
    <origin rpy="0 0 0" xyz="0 0 0"/>
    <axis xyz="0 0 0"/>
    <parent link="irb120_base"/>
    <child link="irb120_base_link"/>
  </joint>
  <!-- ROS-Industrial 'flange' frame: attachment point for EEF models -->
  <link name="irb120_flange"/>
  <joint name="irb120_joint_6-flange" type="fixed">
    <origin rpy="0 0 0" xyz="0 0 0"/>
    <parent link="irb120_link_6"/>
    <child link="irb120_flange"/>
  </joint>
  <!-- ROS-Industrial 'tool0' frame: all-zeros tool frame -->
  <link name="irb120_tool0"/>
  <joint name="irb120_link_6-tool0" type="fixed">
    <origin rpy="0 1.57079632679 0" xyz="0 0 0"/>
    <parent link="irb120_flange"/>
    <child link="irb120_tool0"/>
  </joint>
  <joint name="world-irb120_joint" type="fixed">
    <!-- <origin xyz="0.3625 -0.1125 0" rpy="0 0 ${PI}"/> -->
    <!-- <origin xyz="0.21 0 0" rpy="0 0 0"/> -->
    <origin rpy="0 0 1.5707963267949" xyz="0      0 0"/>
    <parent link="world_base"/>
    <child link="irb120_base"/>
  </joint>
  <link name="robotiq_arg2f_base_link">
    <inertial>
      <origin rpy="0 0 0" xyz="8.625E-08 -4.6583E-06 0.03145"/>
      <mass value="0.22652"/>
      <inertia ixx="0.00020005" ixy="-4.2442E-10" ixz="-2.9069E-10" iyy="0.00017832" iyz="-3.4402E-08" izz="0.00013478"/>
    </inertial>
    <visual>
      <origin rpy="0 0 0" xyz="0 0 0"/>
      <geometry>
        <mesh filename="package://robotiq_2f_85_gripper_visualization/meshes/visual/robotiq_arg2f_85_base_link.dae" scale="0.001 0.001 0.001"/>
      </geometry>
      <material name="">
        <color rgba="0.1 0.1 0.1 1"/>
      </material>
    </visual>
    <collision>
      <origin rpy="0 0 0" xyz="0 0 0"/>
      <geometry>
        <mesh filename="package://robotiq_2f_85_gripper_visualization/meshes/collision/robotiq_arg2f_base_link.stl"/>
      </geometry>
    </collision>
  </link>
  <link name="left_outer_knuckle">
    <!--<inertial>
        <origin xyz="-0.000200000000003065 0.0199435877845359 0.0292245259211331" rpy="0 0 0" />
        <mass value="0.00853198276973456" />
        <inertia ixx="2.89328108496468E-06" ixy="-1.57935047237397E-19" ixz="-1.93980378593255E-19" iyy="1.86719750325683E-06" iyz="-1.21858577871576E-06" izz="1.21905238907251E-06" />
        </inertial> -->
    <visual>
      <origin rpy="0 0 0" xyz="0 0 0"/>
      <geometry>
        <mesh filename="package://robotiq_2f_85_gripper_visualization/meshes/visual/robotiq_arg2f_85_outer_knuckle.dae" scale="0.001 0.001 0.001"/>
      </geometry>
      <material name="">
        <color rgba="0.792156862745098 0.819607843137255 0.933333333333333 1"/>
      </material>
    </visual>
    <collision>
      <origin rpy="0 0 0" xyz="0 0 0"/>
      <geometry>
        <mesh filename="package://robotiq_2f_85_gripper_visualization/meshes/collision/robotiq_arg2f_85_outer_knuckle.dae" scale="0.001 0.001 0.001"/>
      </geometry>
    </collision>
  </link>
  <link name="left_outer_finger">
    <!--<inertial>
        <origin xyz="0.00030115855001899 0.0373907951953854 -0.0208027427000385" rpy="0 0 0" />
        <mass value="0.022614240507152" />
        <inertia ixx="1.52518312458174E-05" ixy="9.76583423954399E-10" ixz="-5.43838577022588E-10" iyy="6.17694243867776E-06" iyz="6.78636130740228E-06" izz="1.16494917907219E-05" />
        </inertial> -->
    <visual>
      <origin rpy="0 0 0" xyz="0 0 0"/>
      <geometry>
        <mesh filename="package://robotiq_2f_85_gripper_visualization/meshes/visual/robotiq_arg2f_85_outer_finger.dae" scale="0.001 0.001 0.001"/>
      </geometry>
      <material name="">
        <color rgba="0.1 0.1 0.1 1"/>
      </material>
    </visual>
    <collision>
      <origin rpy="0 0 0" xyz="0 0 0"/>
      <geometry>
        <mesh filename="package://robotiq_2f_85_gripper_visualization/meshes/collision/robotiq_arg2f_85_outer_finger.dae" scale="0.001 0.001 0.001"/>
      </geometry>
    </collision>
  </link>
  <link name="left_inner_finger">
    <!--<inertial>
        <origin xyz="0.000299999999999317 0.0160078233491243 -0.0136945669206257" rpy="0 0 0" />
        <mass value="0.0104003125914103" />
        <inertia ixx="2.71909453810972E-06" ixy="1.35402465472579E-21" ixz="-7.1817349065269E-22" iyy="7.69100314106116E-07" iyz="6.74715432769696E-07" izz="2.30315190420171E-06" />
        </inertial> -->
    <visual>
      <origin rpy="0 0 0" xyz="0 0 0"/>
      <geometry>
        <mesh filename="package://robotiq_2f_85_gripper_visualization/meshes/visual/robotiq_arg2f_85_inner_finger.dae" scale="0.001 0.001 0.001"/>
      </geometry>
      <material name="">
        <color rgba="0.1 0.1 0.1 1"/>
      </material>
    </visual>
    <collision>
      <origin rpy="0 0 0" xyz="0 0 0"/>
      <geometry>
        <mesh filename="package://robotiq_2f_85_gripper_visualization/meshes/collision/robotiq_arg2f_85_inner_finger.dae" scale="0.001 0.001 0.001"/>
      </geometry>
    </collision>
  </link>
  <!-- <link name="${prefix}${fingerprefix}_inner_finger_pad"> -->
  <link name="left_inner_finger_pad">
    <visual>
      <origin rpy="0 0 -1.570796" xyz="0 0 0"/>
      <geometry>
        <mesh filename="package://robotiq_2f_85_gripper_visualization/meshes/visual/left_cup_plate_gripper_assembly.STL" scale="0.001 0.001 0.001"/>
      </geometry>
      <material name="2f_inner_finger_pad">
        <color rgba="0.9 0.9 0.9 1"/>
      </material>
    </visual>
    <collision>
      <origin rpy="0 0 0" xyz="0 0 0"/>
      <geometry>
        <mesh filename="package://robotiq_2f_85_gripper_visualization/meshes/collision/left_cup_plate_gripper_assembly.STL" scale="0.001 0.001 0.001"/>
      </geometry>
      <material name="2f_inner_finger_pad">
        <color rgba="0.9 0.0 0.0 1"/>
      </material>
    </collision>
  </link>
  <link name="left_inner_knuckle">
    <!--<inertial>
        <origin xyz="0.000123011831763771 0.0507850843201817 0.00103968640075166" rpy="0 0 0" />
       <mass value="0.0271177346495152" />
        <inertia ixx="2.61910379223783E-05" ixy="-2.43616858946494E-07" ixz="-6.37789906117123E-09" iyy="2.8270243746167E-06" iyz="-5.37200748039765E-07" izz="2.83695868220296E-05" />
        </inertial> -->
    <visual>
      <origin rpy="0 0 0" xyz="0 0 0"/>
      <geometry>
        <mesh filename="package://robotiq_2f_85_gripper_visualization/meshes/visual/robotiq_arg2f_85_inner_knuckle.dae" scale="0.001 0.001 0.001"/>
      </geometry>
      <material name="">
        <color rgba="0.1 0.1 0.1 1"/>
      </material>
    </visual>
    <collision>
      <origin rpy="0 0 0" xyz="0 0 0"/>
      <geometry>
        <mesh filename="package://robotiq_2f_85_gripper_visualization/meshes/collision/robotiq_arg2f_85_inner_knuckle.dae" scale="0.001 0.001 0.001"/>
      </geometry>
    </collision>
  </link>
  <link name="right_outer_knuckle">
    <!--<inertial>
        <origin xyz="-0.000200000000003065 0.0199435877845359 0.0292245259211331" rpy="0 0 0" />
        <mass value="0.00853198276973456" />
        <inertia ixx="2.89328108496468E-06" ixy="-1.57935047237397E-19" ixz="-1.93980378593255E-19" iyy="1.86719750325683E-06" iyz="-1.21858577871576E-06" izz="1.21905238907251E-06" />
        </inertial> -->
    <visual>
      <origin rpy="0 0 0" xyz="0 0 0"/>
      <geometry>
        <mesh filename="package://robotiq_2f_85_gripper_visualization/meshes/visual/robotiq_arg2f_85_outer_knuckle.dae" scale="0.001 0.001 0.001"/>
      </geometry>
      <material name="">
        <color rgba="0.792156862745098 0.819607843137255 0.933333333333333 1"/>
      </material>
    </visual>
    <collision>
      <origin rpy="0 0 0" xyz="0 0 0"/>
      <geometry>
        <mesh filename="package://robotiq_2f_85_gripper_visualization/meshes/collision/robotiq_arg2f_85_outer_knuckle.dae" scale="0.001 0.001 0.001"/>
      </geometry>
    </collision>
  </link>
  <link name="right_outer_finger">
    <!--<inertial>
        <origin xyz="0.00030115855001899 0.0373907951953854 -0.0208027427000385" rpy="0 0 0" />
        <mass value="0.022614240507152" />
        <inertia ixx="1.52518312458174E-05" ixy="9.76583423954399E-10" ixz="-5.43838577022588E-10" iyy="6.17694243867776E-06" iyz="6.78636130740228E-06" izz="1.16494917907219E-05" />
        </inertial> -->
    <visual>
      <origin rpy="0 0 0" xyz="0 0 0"/>
      <geometry>
        <mesh filename="package://robotiq_2f_85_gripper_visualization/meshes/visual/robotiq_arg2f_85_outer_finger.dae" scale="0.001 0.001 0.001"/>
      </geometry>
      <material name="">
        <color rgba="0.1 0.1 0.1 1"/>
      </material>
    </visual>
    <collision>
      <origin rpy="0 0 0" xyz="0 0 0"/>
      <geometry>
        <mesh filename="package://robotiq_2f_85_gripper_visualization/meshes/collision/robotiq_arg2f_85_outer_finger.dae" scale="0.001 0.001 0.001"/>
      </geometry>
    </collision>
  </link>
  <link name="right_inner_finger">
    <!--<inertial>
        <origin xyz="0.000299999999999317 0.0160078233491243 -0.0136945669206257" rpy="0 0 0" />
        <mass value="0.0104003125914103" />
        <inertia ixx="2.71909453810972E-06" ixy="1.35402465472579E-21" ixz="-7.1817349065269E-22" iyy="7.69100314106116E-07" iyz="6.74715432769696E-07" izz="2.30315190420171E-06" />
        </inertial> -->
    <visual>
      <origin rpy="0 0 0" xyz="0 0 0"/>
      <geometry>
        <mesh filename="package://robotiq_2f_85_gripper_visualization/meshes/visual/robotiq_arg2f_85_inner_finger.dae" scale="0.001 0.001 0.001"/>
      </geometry>
      <material name="">
        <color rgba="0.1 0.1 0.1 1"/>
      </material>
    </visual>
    <collision>
      <origin rpy="0 0 0" xyz="0 0 0"/>
      <geometry>
        <mesh filename="package://robotiq_2f_85_gripper_visualization/meshes/collision/robotiq_arg2f_85_inner_finger.dae" scale="0.001 0.001 0.001"/>
      </geometry>
    </collision>
  </link>
  <!-- <link name="${prefix}${fingerprefix}_inner_finger_pad"> -->
  <link name="right_inner_finger_pad">
    <visual>
      <origin rpy="0 0 -1.570796" xyz="0 0 0"/>
      <geometry>
        <mesh filename="package://robotiq_2f_85_gripper_visualization/meshes/visual/right_cup_plate_gripper_assembly.STL" scale="0.001 0.001 0.001"/>
      </geometry>
      <material name="2f_inner_finger_pad">
        <color rgba="0.9 0.9 0.9 1"/>
      </material>
    </visual>
    <collision>
      <origin rpy="0 0 0" xyz="0 0 0"/>
      <geometry>
        <mesh filename="package://robotiq_2f_85_gripper_visualization/meshes/collision/right_cup_plate_gripper_assembly.STL" scale="0.001 0.001 0.001"/>
      </geometry>
      <material name="2f_inner_finger_pad">
        <color rgba="0.9 0.0 0.0 1"/>
      </material>
    </collision>
  </link>
  <link name="right_inner_knuckle">
    <!--<inertial>
        <origin xyz="0.000123011831763771 0.0507850843201817 0.00103968640075166" rpy="0 0 0" />
       <mass value="0.0271177346495152" />
        <inertia ixx="2.61910379223783E-05" ixy="-2.43616858946494E-07" ixz="-6.37789906117123E-09" iyy="2.8270243746167E-06" iyz="-5.37200748039765E-07" izz="2.83695868220296E-05" />
        </inertial> -->
    <visual>
      <origin rpy="0 0 0" xyz="0 0 0"/>
      <geometry>
        <mesh filename="package://robotiq_2f_85_gripper_visualization/meshes/visual/robotiq_arg2f_85_inner_knuckle.dae" scale="0.001 0.001 0.001"/>
      </geometry>
      <material name="">
        <color rgba="0.1 0.1 0.1 1"/>
      </material>
    </visual>
    <collision>
      <origin rpy="0 0 0" xyz="0 0 0"/>
      <geometry>
        <mesh filename="package://robotiq_2f_85_gripper_visualization/meshes/collision/robotiq_arg2f_85_inner_knuckle.dae" scale="0.001 0.001 0.001"/>
      </geometry>
    </collision>
  </link>
  <joint name="finger_joint" type="revolute">
    <origin rpy="0 0 3.14159265359" xyz="0 -0.0306011 0.054904"/>
    <parent link="robotiq_arg2f_base_link"/>
    <child link="left_outer_knuckle"/>
    <axis xyz="1 0 0"/>
    <limit effort="1000" lower="0" upper="0.8" velocity="2.0"/>
  </joint>
  <joint name="left_outer_finger_joint" type="fixed">
    <origin rpy="0 0 0" xyz="0 0.0315 -0.0041"/>
    <parent link="left_outer_knuckle"/>
    <child link="left_outer_finger"/>
    <axis xyz="1 0 0"/>
  </joint>
  <joint name="left_inner_knuckle_joint" type="revolute">
    <!-- <origin xyz="0 ${reflect * -0.0127} 0.06142" rpy="${pi / 2 + .725} 0 ${(reflect - 1) * pi / 2}" /> -->
    <origin rpy="0 0 3.14159265359" xyz="0 -0.0127 0.06142"/>
    <parent link="robotiq_arg2f_base_link"/>
    <child link="left_inner_knuckle"/>
    <axis xyz="1 0 0"/>
    <limit effort="1000" lower="0" upper="0.8757" velocity="2.0"/>
    <mimic joint="finger_joint" multiplier="1" offset="0"/>
  </joint>
  <joint name="left_inner_finger_joint" type="revolute">
    <origin rpy="0 0 0" xyz="0 0.0061 0.0471"/>
    <parent link="left_outer_finger"/>
    <child link="left_inner_finger"/>
    <axis xyz="1 0 0"/>
    <limit effort="1000" lower="0" upper="0.8757" velocity="2.0"/>
    <mimic joint="finger_joint" multiplier="-1" offset="0"/>
  </joint>
  <joint name="left_inner_finger_pad_joint" type="fixed">
    <origin rpy="0 0 0" xyz="0 -0.0220203446692936 0.01367"/>
    <parent link="left_inner_finger"/>
    <child link="left_inner_finger_pad"/>
    <axis xyz="0 0 1"/>
  </joint>
  <joint name="right_outer_knuckle_joint" type="revolute">
    <origin rpy="0 0 0" xyz="0 0.0306011 0.054904"/>
    <parent link="robotiq_arg2f_base_link"/>
    <child link="right_outer_knuckle"/>
    <axis xyz="1 0 0"/>
    <limit effort="1000" lower="0" upper="0.81" velocity="2.0"/>
    <mimic joint="finger_joint" multiplier="1" offset="0"/>
  </joint>
  <joint name="right_outer_finger_joint" type="fixed">
    <origin rpy="0 0 0" xyz="0 0.0315 -0.0041"/>
    <parent link="right_outer_knuckle"/>
    <child link="right_outer_finger"/>
    <axis xyz="1 0 0"/>
  </joint>
  <joint name="right_inner_knuckle_joint" type="revolute">
    <!-- <origin xyz="0 ${reflect * -0.0127} 0.06142" rpy="${pi / 2 + .725} 0 ${(reflect - 1) * pi / 2}" /> -->
    <origin rpy="0 0 0.0" xyz="0 0.0127 0.06142"/>
    <parent link="robotiq_arg2f_base_link"/>
    <child link="right_inner_knuckle"/>
    <axis xyz="1 0 0"/>
    <limit effort="1000" lower="0" upper="0.8757" velocity="2.0"/>
    <mimic joint="finger_joint" multiplier="1" offset="0"/>
  </joint>
  <joint name="right_inner_finger_joint" type="revolute">
    <origin rpy="0 0 0" xyz="0 0.0061 0.0471"/>
    <parent link="right_outer_finger"/>
    <child link="right_inner_finger"/>
    <axis xyz="1 0 0"/>
    <limit effort="1000" lower="0" upper="0.8757" velocity="2.0"/>
    <mimic joint="finger_joint" multiplier="-1" offset="0"/>
  </joint>
  <joint name="right_inner_finger_pad_joint" type="fixed">
    <origin rpy="0 0 0" xyz="0 -0.0220203446692936 0.01367"/>
    <parent link="right_inner_finger"/>
    <child link="right_inner_finger_pad"/>
    <axis xyz="0 0 1"/>
  </joint>
  <transmission name="finger_joint_trans">
    <type>transmission_interface/SimpleTransmission</type>
    <joint name="finger_joint">
      <hardwareInterface>PositionJointInterface</hardwareInterface>
    </joint>
    <actuator name="finger_joint_motor">
      <mechanicalReduction>1</mechanicalReduction>
    </actuator>
  </transmission>
  <link name="robotiq_gripper_coupling">
    <visual>
      <origin rpy="0 0 0" xyz="0 0 0.004"/>
      <geometry>
        <mesh filename="package://robotiq_2f_85_gripper_visualization/meshes/visual/robotiq_gripper_coupling.stl" scale="0.001 0.001 0.001"/>
      </geometry>
      <material name="robotiq_gripper_coupling">
        <color rgba="0.1 0.1 0.1 1"/>
      </material>
    </visual>
    <collision>
      <origin rpy="0 0 0" xyz="0 0 0.004"/>
      <geometry>
        <mesh filename="package://robotiq_2f_85_gripper_visualization/meshes/visual/robotiq_gripper_coupling.stl" scale="0.001 0.001 0.001"/>
      </geometry>
    </collision>
  </link>
  <joint name="irb120_2f_joint" type="fixed">
    <parent link="irb120_tool0"/>
    <child link="robotiq_gripper_coupling"/>
    <!-- <child link="robotiq_arg2f_base_link"/> -->
    <origin rpy="0 0 0" xyz="0 0 0"/>
  </joint>
  <joint name="2f_gripper_coupling_joint" type="fixed">
    <parent link="robotiq_gripper_coupling"/>
    <child link="robotiq_arg2f_base_link"/>
    <origin rpy="0 0 1.570796" xyz="0 0 0.008"/>
  </joint>
  <link name="cup_grasp_point">
    <visual>
      <origin rpy="0 0 0" xyz="0 0 0"/>
      <geometry>
        <box size="0.015 0.015 0.015"/>
        <!-- <box size="0.1 0.1 0.1"/> -->
      </geometry>
      <material name="cup_grasp_point">
        <color rgba="1 0 1 0.1"/>
      </material>
    </visual>
  </link>
  <joint name="cup_grasp_point" type="fixed">
    <parent link="irb120_tool0"/>
    <child link="cup_grasp_point"/>
    <!-- <origin xyz="0 0 0.25" rpy="0 0 1.570796"/> -->
    <origin rpy="0 0 0" xyz="0 0 0.2"/>
  </joint>
  <link name="plate_grasp_point">
    <visual>
      <origin rpy="0 0 0" xyz="0 0 0"/>
      <geometry>
        <box size="0.015 0.015 0.015"/>
        <!-- <box size="0.1 0.1 0.1"/> -->
      </geometry>
      <material name="plate_grasp_point">
        <color rgba="1 0 1 0.1"/>
      </material>
    </visual>
  </link>
  <joint name="plate_grasp_point" type="fixed">
    <parent link="irb120_tool0"/>
    <child link="plate_grasp_point"/>
    <!-- <origin xyz="0 0 0.25" rpy="0 0 0.261799"/> -->
    <origin rpy="0 0 0" xyz="0.052 0 0.31"/>
  </joint>
</robot>

